Workbook

Sheet NVIDIA 
A1: Date | B1: Price | C1: Open | D1: High | E1: Low | F1: Vol. | G1: Change % | H1: Ln Return
A2: 46155 | B2: 225.83 | C2: 224.93 | D2: 227.84 | E2: 221.57 | F2: 150.41M | G2: 0.0229 | H2: =LN(B2/B3) -> 0.022615773 | J2: Daily return | K2: =AVERAGE(H2:H752) -> 0.0027353027
A3: 46154 | B3: 220.78 | C3: 218.54 | D3: 223.75 | E3: 214.92 | F3: 159.18M | G3: 0.0061 | H3: =LN(B3/B4) -> 0.006087884 | J3: Annual return | K3: =K2*252 -> 0.68929627
A4: 46153 | B4: 219.44 | C4: 214.04 | D4: 222.3 | E4: 213.89 | F4: 160.69M | G4: 0.0197 | H4: =LN(B4/B5) -> 0.019511018 | J4: Daily volatility | K4: =STDEV(H2:H752) -> 0.030471767
A5: 46150 | B5: 215.2 | C5: 213.03 | D5: 217.8 | E5: 212.89 | F5: 136.42M | G5: 0.0175 | H5: =LN(B5/B6) -> 0.01734283 | J5: annual volatility | K5: =K4*SQRT(252) -> 0.4837243
A6: 46149 | B6: 211.5 | C6: 208.34 | D6: 214.2 | E6: 206.5 | F6: 168.31M | G6: 0.0177 | H6: =LN(B6/B7) -> 0.017504561
A7: 46148 | B7: 207.83 | C7: 199.89 | D7: 208.26 | E7: 198.61 | F7: 188.36M | G7: 0.0577 | H7: =LN(B7/B8) -> 0.056058007
A8: 46147 | B8: 196.5 | C8: 199.3 | D8: 200.24 | E8: 196.03 | F8: 113.41M | G8: -0.01 | H8: =LN(B8/B9) -> -0.010025908
A9: 46146 | B9: 198.48 | C9: 199.5 | D9: 201.73 | E9: 194.74 | F9: 125.37M | G9: 0.0002 | H9: =LN(B9/B10) -> 0.00015116015
A10: 46143 | B10: 198.45 | C10: 201.28 | D10: 203 | E10: 197.12 | F10: 128.65M | G10: -0.0056 | H10: =LN(B10/B11) -> -0.0056278728
A11: 46142 | B11: 199.57 | C11: 209.93 | D11: 210.3 | E11: 198.7 | F11: 225.24M | G11: -0.0463 | H11: =LN(B11/B12) -> -0.047364657
A12: 46141 | B12: 209.25 | C12: 212.7 | D12: 212.72 | E12: 207.58 | F12: 123.71M | G12: -0.0184 | H12: =LN(B12/B13) -> -0.01856026
A13: 46140 | B13: 213.17 | C13: 209.49 | D13: 214.73 | E13: 208.2 | F13: 180.28M | G13: -0.0159 | H13: =LN(B13/B14) -> -0.016008532
A14: 46139 | B14: 216.61 | C14: 209.65 | D14: 216.82 | E14: 207.38 | F14: 187.17M | G14: 0.04 | H14: =LN(B14/B15) -> 0.039263187
A15: 46136 | B15: 208.27 | C15: 199.96 | D15: 210.95 | E15: 199.81 | F15: 214.13M | G15: 0.0432 | H15: =LN(B15/B16) -> 0.04231957
A16: 46135 | B16: 199.64 | C16: 202.46 | D16: 203.83 | E16: 197.22 | F16: 113.56M | G16: -0.0141 | H16: =LN(B16/B17) -> -0.014224142
A17: 46134 | B17: 202.5 | C17: 200.99 | D17: 202.5 | E17: 199 | F17: 107.50M | G17: 0.0131 | H17: =LN(B17/B18) -> 0.0130227
... A752: 45062 | B752: 29.21 | C752: 28.84 | D752: 29.87 | E752: 28.83 | F752: 449.40M | G752: 0.009 | H752: =LN(B752/B753) -> 0.0089409124
A753: 45061 | B753: 28.95 | C753: 28.51 | D753: 28.97 | E753: 28.15 | F753: 293.93M | G753: 0.0216

Sheet APPL
A1: Date | B1: Price | C1: Open | D1: High | E1: Low | F1: Vol. | G1: Change % | H1: Ln return
A2: 46155 | B2: 298.87 | C2: 293.5 | D2: 300.92 | E2: 293.5 | F2: 52.68M | G2: 0.0138 | H2: =LN(B2/B3) -> 0.013711536 | J2: Daily return | K2: =AVERAGE(H2:H752) -> 0.00073516288
A3: 46154 | B3: 294.8 | C3: 292.56 | D3: 295.27 | E3: 292.56 | F3: 45.75M | G3: 0.0072 | H3: =LN(B3/B4) -> 0.0072172983 | J3: Annual return | K3: =K2*252 -> 0.18526105
A4: 46153 | B4: 292.68 | C4: 291.98 | D4: 293.88 | E4: 290.23 | F4: 42.25M | G4: -0.0022 | H4: =LN(B4/B5) -> -0.0021843012 | J4: Daily volatility | K4: =STDEV(H2:H752) -> 0.016168042
A5: 46150 | B5: 293.32 | C5: 290.01 | D5: 294.76 | E5: 290 | F5: 52.69M | G5: 0.0205 | H5: =LN(B5/B6) -> 0.02025002 | J5: annual volatility | K5: =K4*SQRT(252) -> 0.25665971
A6: 46149 | B6: 287.44 | C6: 289.27 | D6: 292.13 | E6: 285.78 | F6: 45.22M | G6: -0.0002 | H6: =LN(B6/B7) -> -0.00024349944
A7: 46148 | B7: 287.51 | C7: 281.92 | D7: 288.03 | E7: 281.07 | F7: 58.34M | G7: 0.0117 | H7: =LN(B7/B8) -> 0.011649802
A8: 46147 | B8: 284.18 | C8: 276.92 | D8: 284.57 | E8: 276.5 | F8: 49.31M | G8: 0.0266 | H8: =LN(B8/B9) -> 0.026204241
A9: 46146 | B9: 276.83 | C9: 279.65 | D9: 280.63 | E9: 274.86 | F9: 46.67M | G9: -0.0118 | H9: =LN(B9/B10) -> -0.011885879
A10: 46143 | B10: 280.14 | C10: 278.86 | D10: 287.22 | E10: 278.37 | F10: 79.92M | G10: 0.0324 | H10: =LN(B10/B11) -> 0.031879978
A11: 46142 | B11: 271.35 | C11: 270.5 | D11: 276 | E11: 268.14 | F11: 91.85M | G11: 0.0044 | H11: =LN(B11/B12) -> 0.00435811
A12: 46141 | B12: 270.17 | C12: 267.55 | D12: 271.04 | E12: 267.04 | F12: 30.05M | G12: -0.002 | H12: =LN(B12/B13) -> -0.0019967467
A13: 46140 | B13: 270.71 | C13: 272.33 | D13: 273.23 | E13: 268.66 | F13: 40.02M | G13: 0.0116 | H13: =LN(B13/B14) -> 0.01151744
A14: 46139 | B14: 267.61 | C14: 266.09 | D14: 268.36 | E14: 265.07 | F14: 41.47M | G14: -0.0127 | H14: =LN(B14/B15) -> -0.012809502
A15: 46136 | B15: 271.06 | C15: 272.76 | D15: 273.06 | E15: 269.65 | F15: 38.16M | G15: -0.0087 | H15: =LN(B15/B16) -> -0.008705449
A16: 46135 | B16: 273.43 | C16: 275.05 | D16: 275.77 | E16: 271.65 | F16: 33.40M | G16: 0.001 | H16: =LN(B16/B17) -> 0.0009513356
A17: 46134 | B17: 273.17 | C17: 267.82 | D17: 273.74 | E17: 266.87 | F17: 43.25M | G17: 0.0263 | H17: =LN(B17/B18) -> 0.02595911
... A752: 45062 | B752: 172.07 | C752: 171.99 | D752: 173.14 | E752: 171.8 | F752: 42.11M | G752: 0 | H752: =LN(B752/B753) -> 0
A753: 45061 | B753: 172.07 | C753: 173.16 | D753: 173.21 | E753: 171.47 | F753: 37.27M | G753: -0.0029

Sheet Amazon
A1: Date | B1: Price | C1: Open | D1: High | E1: Low | F1: Vol. | G1: Change % | H1: Ln return
A2: 46155 | B2: 270.13 | C2: 264.43 | D2: 270.72 | E2: 263.2 | F2: 39.67M | G2: 0.0162 | H2: =LN(B2/B3) -> 0.016083937 | J2: Daily return | K2: =AVERAGE(H2:H752) -> 0.0011818548
A3: 46154 | B3: 265.82 | C3: 266.71 | D3: 267.65 | E3: 262.63 | F3: 36.78M | G3: -0.0118 | H3: =LN(B3/B4) -> -0.011854816 | J3: Annual return | K3: =K2*252 -> 0.29782741
A4: 46153 | B4: 268.99 | C4: 269.83 | D4: 273.63 | E4: 268.48 | F4: 38.18M | G4: -0.0135 | H4: =LN(B4/B5) -> -0.013624742 | J4: Daily volatility | K4: =STDEV(H2:H752) -> 0.019500768
A5: 46150 | B5: 272.68 | C5: 271.63 | D5: 274 | E5: 269.95 | F5: 34.73M | G5: 0.0056 | H5: =LN(B5/B6) -> 0.005553016 | J5: annual volatility | K5: =K4*SQRT(252) -> 0.3095651
A6: 46149 | B6: 271.17 | C6: 275.02 | D6: 276.63 | E6: 270.49 | F6: 35.89M | G6: -0.0139 | H6: =LN(B6/B7) -> -0.013988803
A7: 46148 | B7: 274.99 | C7: 272.89 | D7: 277.8 | E7: 272.21 | F7: 44.55M | G7: 0.0053 | H7: =LN(B7/B8) -> 0.0052503129
A8: 46147 | B8: 273.55 | C8: 276.08 | D8: 278.56 | E8: 272.38 | F8: 41.91M | G8: 0.0055 | H8: =LN(B8/B9) -> 0.0054985476
A9: 46146 | B9: 272.05 | C9: 268.8 | D9: 276.1 | E9: 268.8 | F9: 49.08M | G9: 0.0141 | H9: =LN(B9/B10) -> 0.014029213
A10: 46143 | B10: 268.26 | C10: 265.58 | D10: 273.32 | E10: 262.74 | F10: 50.83M | G10: 0.0121 | H10: =LN(B10/B11) -> 0.012000444
A11: 46142 | B11: 265.06 | C11: 273.17 | D11: 273.88 | E11: 256.16 | F11: 100.97M | G11: 0.0077 | H11: =LN(B11/B12) -> 0.0076501036
A12: 46141 | B12: 263.04 | C12: 257.99 | D12: 265.91 | E12: 257.7 | F12: 72.37M | G12: 0.0129 | H12: =LN(B12/B13) -> 0.012778993
A13: 46140 | B13: 259.7 | C13: 258.39 | D13: 261.03 | E13: 256.63 | F13: 42.20M | G13: -0.0054 | H13: =LN(B13/B14) -> -0.0054529531
A14: 46139 | B14: 261.12 | C14: 263.46 | D14: 264.15 | E14: 260.34 | F14: 44.91M | G14: -0.0109 | H14: =LN(B14/B15) -> -0.010931152
A15: 46136 | B15: 263.99 | C15: 259.98 | D15: 264.5 | E15: 257.68 | F15: 53.78M | G15: 0.0349 | H15: =LN(B15/B16) -> 0.034334002
A16: 46135 | B16: 255.08 | C16: 255.39 | D16: 258.79 | E16: 253.07 | F16: 39.09M | G16: -0.0011 | H16: =LN(B16/B17) -> -0.0010970928
A17: 46134 | B17: 255.36 | C17: 252.44 | D17: 255.94 | E17: 250.33 | F17: 36.07M | G17: 0.0218 | H17: =LN(B17/B18) -> 0.021573461
... A752: 45062 | B752: 113.4 | C752: 111.05 | D752: 114.79 | E752: 111.05 | F752: 71.47M | G752: 0.0198 | H752: =LN(B752/B753) -> 0.019591009
A753: 45061 | B753: 111.2 | C753: 111.15 | D753: 112.29 | E753: 109.25 | F753: 53.01M | G753: 0.0085

Sheet Alphabet
A1: Date | B1: Price | C1: Open | D1: High | E1: Low | F1: Vol. | G1: Change % | H1: Ln return
A2: 46155 | B2: 402.62 | C2: 385.6 | D2: 403.7 | E2: 385 | F2: 28.14M | G2: 0.0394 | H2: =LN(B2/B3) -> 0.038664512 | J2: Daily return | K2: =AVERAGE(H2:H752) -> 0.0016511532
A3: 46154 | B3: 387.35 | C3: 387.34 | D3: 388.52 | E3: 382.77 | F3: 26.02M | G3: -0.0033 | H3: =LN(B3/B4) -> -0.0033247882 | J3: Annual return | K3: =K2*252 -> 0.41609062
A4: 46153 | B4: 388.64 | C4: 393.64 | D4: 397.44 | E4: 388.47 | F4: 30.75M | G4: -0.0303 | H4: =LN(B4/B5) -> -0.030809085 | J4: Daily volatility | K4: =STDEV(H2:H752) -> 0.018616259
A5: 46150 | B5: 400.8 | C5: 397 | D5: 402 | E5: 396.36 | F5: 21.46M | G5: 0.0071 | H5: =LN(B5/B6) -> 0.0070356704 | J5: annual volatility | K5: =K4*SQRT(252) -> 0.29552394
A6: 46149 | B6: 397.99 | C6: 399.92 | D6: 400.1 | E6: 392.68 | F6: 24.43M | G6: -0.0001 | H6: =LN(B6/B7) -> -0.00012562341
A7: 46148 | B7: 398.04 | C7: 394.24 | D7: 399.85 | E7: 392.76 | F7: 31.31M | G7: 0.0247 | H7: =LN(B7/B8) -> 0.024439529
A8: 46147 | B8: 388.43 | C8: 386.23 | D8: 392.82 | E8: 384.02 | F8: 23.88M | G8: 0.0135 | H8: =LN(B8/B9) -> 0.013425456
A9: 46146 | B9: 383.25 | C9: 385.63 | D9: 387.38 | E9: 379.79 | F9: 26.30M | G9: -0.0063 | H9: =LN(B9/B10) -> -0.0063464202
A10: 46143 | B10: 385.69 | C10: 381.63 | D10: 386.76 | E10: 379.05 | F10: 30.11M | G10: 0.0023 | H10: =LN(B10/B11) -> 0.0023102192
A11: 46142 | B11: 384.8 | C11: 374.07 | D11: 385.84 | E11: 365.82 | F11: 72.04M | G11: 0.0996 | H11: =LN(B11/B12) -> 0.094962008
A12: 46141 | B12: 349.94 | C12: 347.57 | D12: 355.79 | E12: 344.21 | F12: 35.38M | G12: 0.0005 | H12: =LN(B12/B13) -> 0.0004573258
A13: 46140 | B13: 349.78 | C13: 348.55 | D13: 352.42 | E13: 346.12 | F13: 27.82M | G13: -0.0016 | H13: =LN(B13/B14) -> -0.0015997261
A14: 46139 | B14: 350.34 | C14: 345.98 | D14: 353.18 | E14: 342.73 | F14: 28.58M | G14: 0.0172 | H14: =LN(B14/B15) -> 0.017100339
A15: 46136 | B15: 344.4 | C15: 338.73 | D15: 345.27 | E15: 335.39 | F15: 26.43M | G15: 0.0163 | H15: =LN(B15/B16) -> 0.016128202
A16: 46135 | B16: 338.89 | C16: 341.18 | D16: 341.96 | E16: 336.18 | F16: 18.65M | G16: -0.0013 | H16: =LN(B16/B17) -> -0.001268044
A17: 46134 | B17: 339.32 | C17: 337.02 | D17: 339.82 | E17: 335.17 | F17: 20.29M | G17: 0.0212 | H17: =LN(B17/B18) -> 0.020935533
... A752: 45062 | B752: 119.51 | C752: 116.49 | D752: 120.75 | E752: 116.43 | F752: 45.04M | G752: 0.0257 | H752: =LN(B752/B753) -> 0.025422944
A753: 45061 | B753: 116.51 | C753: 116.11 | D753: 118.48 | E753: 116.01 | F753: 36.27M | G753: -0.0085

Sheet meta
A1: Date | B1: Price | C1: Open | D1: High | E1: Low | F1: Vol. | G1: Change % | H1: Ln return
A2: 46155 | B2: 616.63 | C2: 598.83 | D2: 619.9 | E2: 596.66 | F2: 14.63M | G2: 0.0226 | H2: =LN(B2/B3) -> 0.022351971 | J2: Daily return | K2: =AVERAGE(H2:H752) -> 0.0012628383
A3: 46154 | B3: 603 | C3: 594.82 | D3: 603.74 | E3: 592.6 | F3: 11.35M | G3: 0.0069 | H3: =LN(B3/B4) -> 0.0068893488 | J3: Annual return | K3: =K2*252 -> 0.31823525
A4: 46153 | B4: 598.86 | C4: 604.57 | D4: 604.91 | E4: 598.08 | F4: 15.94M | G4: -0.0177 | H4: =LN(B4/B5) -> -0.017824368 | J4: Daily volatility | K4: =STDEV(H2:H752) -> 0.022450105
A5: 46150 | B5: 609.63 | C5: 615.2 | D5: 616.77 | E5: 606.06 | F5: 13.56M | G5: -0.0116 | H5: =LN(B5/B6) -> -0.011708819 | J5: annual volatility | K5: =K4*SQRT(252) -> 0.35638437
A6: 46149 | B6: 616.81 | C6: 614.72 | D6: 624.98 | E6: 613.54 | F6: 12.31M | G6: 0.0064 | H6: =LN(B6/B7) -> 0.0063918766
A7: 46148 | B7: 612.88 | C7: 601.05 | D7: 619.95 | E7: 598.1 | F7: 19.92M | G7: 0.0131 | H7: =LN(B7/B8) -> 0.013006818
A8: 46147 | B8: 604.96 | C8: 613.31 | D8: 614.35 | E8: 600.36 | F8: 17.17M | G8: -0.0089 | H8: =LN(B8/B9) -> -0.0089685224
A9: 46146 | B9: 610.41 | C9: 607.93 | D9: 614 | E9: 602.75 | F9: 16.20M | G9: 0.0027 | H9: =LN(B9/B10) -> 0.0027396154
A10: 46143 | B10: 608.74 | C10: 614.69 | D10: 618.88 | E10: 606.11 | F10: 21.40M | G10: -0.0052 | H10: =LN(B10/B11) -> -0.0051939657
A11: 46142 | B11: 611.91 | C11: 619.32 | D11: 620.85 | E11: 600 | F11: 52.76M | G11: -0.0855 | H11: =LN(B11/B12) -> -0.089378203
A12: 46141 | B12: 669.12 | C12: 668.91 | D12: 674.25 | E12: 663.81 | F12: 18.95M | G12: -0.0033 | H12: =LN(B12/B13) -> -0.0033122988
A13: 46140 | B13: 671.34 | C13: 674.24 | D13: 678.18 | E13: 665.63 | F13: 10.61M | G13: -0.0107 | H13: =LN(B13/B14) -> -0.010785609
A14: 46139 | B14: 678.62 | C14: 670.99 | D14: 682.5 | E14: 670.84 | F14: 12.81M | G14: 0.0053 | H14: =LN(B14/B15) -> 0.00530419
A15: 46136 | B15: 675.03 | C15: 660.32 | D15: 680.67 | E15: 653.84 | F15: 13.35M | G15: 0.0241 | H15: =LN(B15/B16) -> 0.023806008
A16: 46135 | B16: 659.15 | C16: 663.7 | D16: 669.56 | E16: 653.05 | F16: 11.67M | G16: -0.0231 | H16: =LN(B16/B17) -> -0.023346664
A17: 46134 | B17: 674.72 | C17: 674.35 | D17: 678.38 | E17: 669.75 | F17: 9.22M | G17: 0.0088 | H17: =LN(B17/B18) -> 0.0087529214
... A752: 45062 | B752: 238.82 | C752: 235.79 | D752: 239.63 | E752: 235.52 | F752: 18.16M | G752: -0.0002 | H752: =LN(B752/B753) -> -0.00016747614
A753: 45061 | B753: 238.86 | C753: 236.92 | D753: 240.26 | E753: 235.33 | F753: 20.65M | G753: 0.0216

Sheet J&J
A1: Date | B1: Price | C1: Open | D1: High | E1: Low | F1: Vol. | G1: Change % | H1: Ln return
A2: 46155 | B2: 230.42 | C2: 225.82 | D2: 230.8 | E2: 225.44 | F2: 7.46M | G2: 0.0275 | H2: =LN(B2/B3) -> 0.027097638 | J2: Daily return | K2: =AVERAGE(H2:H752) -> 0.00048940929
A3: 46154 | B3: 224.26 | C3: 223 | D3: 227.65 | E3: 221.65 | F3: 8.63M | G3: 0.0128 | H3: =LN(B3/B4) -> 0.012699581 | J3: Annual return | K3: =K2*252 -> 0.12333114
A4: 46153 | B4: 221.43 | C4: 221.32 | D4: 223.28 | E4: 220.37 | F4: 6.22M | G4: 0.0005 | H4: =LN(B4/B5) -> 0.00049689442 | J4: Daily volatility | K4: =STDEV(H2:H752) -> 0.010860985
A5: 46150 | B5: 221.32 | C5: 222.94 | D5: 223.37 | E5: 220.92 | F5: 5.55M | G5: -0.0053 | H5: =LN(B5/B6) -> -0.0053624264 | J5: annual volatility | K5: =K4*SQRT(252) -> 0.17241279
A6: 46149 | B6: 222.51 | C6: 224.78 | D6: 224.78 | E6: 220.63 | F6: 7.27M | G6: -0.0094 | H6: =LN(B6/B7) -> -0.0094380411
A7: 46148 | B7: 224.62 | C7: 225.25 | D7: 226.34 | E7: 222.95 | F7: 7.98M | G7: -0.0041 | H7: =LN(B7/B8) -> -0.0041317783
A8: 46147 | B8: 225.55 | C8: 225.39 | D8: 226.53 | E8: 224.9 | F8: 5.56M | G8: 0.006 | H8: =LN(B8/B9) -> 0.0060033532
A9: 46146 | B9: 224.2 | C9: 225.51 | D9: 227.07 | E9: 223.58 | F9: 8.22M | G9: -0.0132 | H9: =LN(B9/B10) -> -0.013248161
A10: 46143 | B10: 227.19 | C10: 229.06 | D10: 229.77 | E10: 227.02 | F10: 6.86M | G10: -0.0116 | H10: =LN(B10/B11) -> -0.01164025
A11: 46142 | B11: 229.85 | C11: 227.95 | D11: 231.16 | E11: 227.81 | F11: 8.16M | G11: 0.011 | H11: =LN(B11/B12) -> 0.010936242
A12: 46141 | B12: 227.35 | C12: 225.52 | D12: 228.71 | E12: 224.86 | F12: 7.07M | G12: -0.0019 | H12: =LN(B12/B13) -> -0.0019334716
A13: 46140 | B13: 227.79 | C13: 227.73 | D13: 231.03 | E13: 226.37 | F13: 7.18M | G13: 0.0109 | H13: =LN(B13/B14) -> 0.010813779
A14: 46139 | B14: 225.34 | C14: 225.77 | D14: 227.91 | E14: 224.35 | F14: 7.90M | G14: -0.0095 | H14: =LN(B14/B15) -> -0.0095398657
A15: 46136 | B15: 227.5 | C15: 229.03 | D15: 229.99 | E15: 227.02 | F15: 6.07M | G15: -0.0137 | H15: =LN(B15/B16) -> -0.013751172
A16: 46135 | B16: 230.65 | C16: 227.25 | D16: 231.39 | E16: 227.03 | F16: 7.10M | G16: 0.0201 | H16: =LN(B16/B17) -> 0.019924031
A17: 46134 | B17: 226.1 | C17: 226.18 | D17: 227.48 | E17: 223.77 | F17: 9.00M | G17: -0.0003 | H17: =LN(B17/B18) -> -0.0002653341
... A752: 45062 | B752: 159.34 | C752: 159.06 | D752: 160.25 | E752: 158.53 | F752: 5.60M | G752: -0.0013 | H752: =LN(B752/B753) -> -0.0013170688
A753: 45061 | B753: 159.55 | C753: 160.8 | D753: 161.03 | E753: 158.94 | F753: 5.10M | G753: -0.0077

Sheet JPM
A1: Date | B1: Price | C1: Open | D1: High | E1: Low | F1: Vol. | G1: Change % | H1: Ln return
A2: 46155 | B2: 300.25 | C2: 302.27 | D2: 303 | E2: 300.07 | F2: 7.71M | G2: -0.0152 | H2: =LN(B2/B3) -> -0.015302796 | J2: Daily return | K2: =AVERAGE(H2:H752) -> 0.0010621018
A3: 46154 | B3: 304.88 | C3: 300.02 | D3: 306.06 | E3: 295.55 | F3: 9.50M | G3: 0.0163 | H3: =LN(B3/B4) -> 0.016135782 | J3: Annual return | K3: =K2*252 -> 0.26764965
A4: 46153 | B4: 300 | C4: 302.1 | D4: 303.19 | E4: 298.88 | F4: 9.51M | G4: -0.007 | H4: =LN(B4/B5) -> -0.0069756137 | J4: Daily volatility | K4: =STDEV(H2:H752) -> 0.014347035
A5: 46150 | B5: 302.1 | C5: 308.25 | D5: 308.99 | E5: 300.5 | F5: 9.46M | G5: -0.0136 | H5: =LN(B5/B6) -> -0.013708977 | J5: annual volatility | K5: =K4*SQRT(252) -> 0.22775212
A6: 46149 | B6: 306.27 | C6: 314.65 | D6: 316.3 | E6: 306.14 | F6: 8.36M | G6: -0.0274 | H6: =LN(B6/B7) -> -0.027788062
A7: 46148 | B7: 314.9 | C7: 311.45 | D7: 316.26 | E7: 311.35 | F7: 8.63M | G7: 0.0178 | H7: =LN(B7/B8) -> 0.01762019
A8: 46147 | B8: 309.4 | C8: 307.71 | D8: 310.97 | E8: 306.8 | F8: 6.32M | G8: 0.0057 | H8: =LN(B8/B9) -> 0.005672165
A9: 46146 | B9: 307.65 | C9: 310.62 | D9: 310.65 | E9: 306.51 | F9: 7.34M | G9: -0.0154 | H9: =LN(B9/B10) -> -0.015545691
A10: 46143 | B10: 312.47 | C10: 313.95 | D10: 316.08 | E10: 311.83 | F10: 6.14M | G10: -0.0024 | H10: =LN(B10/B11) -> -0.0024292804
A11: 46142 | B11: 313.23 | C11: 307.07 | D11: 314.1 | E11: 306.57 | F11: 8.87M | G11: 0.0129 | H11: =LN(B11/B12) -> 0.012787734
A12: 46141 | B12: 309.25 | C12: 310.57 | D12: 312.05 | E12: 307.29 | F12: 8.03M | G12: -0.0071 | H12: =LN(B12/B13) -> -0.0070888004
A13: 46140 | B13: 311.45 | C13: 315.2 | D13: 315.45 | E13: 311.17 | F13: 7.40M | G13: -0.0006 | H13: =LN(B13/B14) -> -0.00057777494
A14: 46139 | B14: 311.63 | C14: 306.88 | D14: 312.58 | E14: 306.88 | F14: 7.93M | G14: 0.0109 | H14: =LN(B14/B15) -> 0.010808126
A15: 46136 | B15: 308.28 | C15: 311.15 | D15: 311.15 | E15: 307.89 | F15: 5.22M | G15: -0.0109 | H15: =LN(B15/B16) -> -0.011000643
A16: 46135 | B16: 311.69 | C16: 313.52 | D16: 314.99 | E16: 308.89 | F16: 6.97M | G16: -0.0042 | H16: =LN(B16/B17) -> -0.0042579821
A17: 46134 | B17: 313.02 | C17: 314.85 | D17: 315.15 | E17: 311.94 | F17: 5.55M | G17: 0.0001 | H17: =LN(B17/B18) -> 6.3895722e-05
... A752: 45062 | B752: 134.32 | C752: 135.46 | D752: 135.94 | E752: 133.96 | F752: 6.48M | G752: -0.0067 | H752: =LN(B752/B753) -> -0.0067520197
A753: 45061 | B753: 135.23 | C753: 134.27 | D753: 135.67 | E753: 133.96 | F753: 7.64M | G753: 0.0084

Sheet Coca-Cola
A1: Date | B1: Price | C1: Open | D1: High | E1: Low | F1: Vol. | G1: Change % | H1: Ln Return
A2: 46155 | B2: 80.26 | C2: 79.86 | D2: 81.03 | E2: 79.84 | F2: 12.36M | G2: 0.0029 | H2: =LN(B2/B3) -> 0.0028698005 | J2: Daily return | K2: =AVERAGE(H2:H752) -> 0.00030269803
A3: 46154 | B3: 80.03 | C3: 79 | D3: 80.32 | E3: 78.28 | F3: 19.88M | G3: 0.0174 | H3: =LN(B3/B4) -> 0.017266797 | J3: Annual return | K3: =K2*252 -> 0.076279904
A4: 46153 | B4: 78.66 | C4: 78.16 | D4: 78.73 | E4: 77.84 | F4: 10.97M | G4: 0.0031 | H4: =LN(B4/B5) -> 0.0030557701 | J4: Daily volatility | K4: =STDEV(H2:H752) -> 0.0097058476
A5: 46150 | B5: 78.42 | C5: 78.57 | D5: 79.2 | E5: 78.11 | F5: 12.45M | G5: -0.0001 | H5: =LN(B5/B6) -> -0.00012751036 | J5: annual volatility | K5: =K4*SQRT(252) -> 0.15407555
A6: 46149 | B6: 78.43 | C6: 78.79 | D6: 79.14 | E6: 78.1 | F6: 16.53M | G6: -0.0101 | H6: =LN(B6/B7) -> -0.010148508
A7: 46148 | B7: 79.23 | C7: 78.78 | D7: 79.33 | E7: 78.57 | F7: 14.06M | G7: 0.0096 | H7: =LN(B7/B8) -> 0.0095111997
A8: 46147 | B8: 78.48 | C8: 78.19 | D8: 78.78 | E8: 77.74 | F8: 11.64M | G8: 0.0037 | H8: =LN(B8/B9) -> 0.0037020531
A9: 46146 | B9: 78.19 | C9: 78.06 | D9: 78.77 | E9: 77.73 | F9: 12.67M | G9: -0.005 | H9: =LN(B9/B10) -> -0.004975452
A10: 46143 | B10: 78.58 | C10: 79.29 | D10: 79.64 | E10: 78.04 | F10: 12.61M | G10: -0.0023 | H10: =LN(B10/B11) -> -0.0022880396
A11: 46142 | B11: 78.76 | C11: 78.79 | D11: 79.12 | E11: 78.32 | F11: 15.14M | G11: -0.0014 | H11: =LN(B11/B12) -> -0.0013956736
A12: 46141 | B12: 78.87 | C12: 78.37 | D12: 79.28 | E12: 78.19 | F12: 18.29M | G12: 0.0066 | H12: =LN(B12/B13) -> 0.0066149586
A13: 46140 | B13: 78.35 | C13: 79.52 | D13: 80.32 | E13: 78.07 | F13: 30.71M | G13: 0.0386 | H13: =LN(B13/B14) -> 0.03784833
A14: 46139 | B14: 75.44 | C14: 76.71 | D14: 76.71 | E14: 75.4 | F14: 15.81M | G14: -0.0155 | H14: =LN(B14/B15) -> -0.015651007
A15: 46136 | B15: 76.63 | C15: 76.71 | D15: 77 | E15: 76.17 | F15: 12.01M | G15: 0.0046 | H15: =LN(B15/B16) -> 0.0045778643
A16: 46135 | B16: 76.28 | C16: 75.44 | D16: 76.66 | E16: 75.16 | F16: 12.06M | G16: 0.0221 | H16: =LN(B16/B17) -> 0.02186821
A17: 46134 | B17: 74.63 | C17: 74.9 | D17: 75.38 | E17: 74.55 | F17: 9.35M | G17: -0.0009 | H17: =LN(B17/B18) -> -0.000937521
... A752: 45062 | B752: 63.22 | C752: 63.9 | D752: 63.9 | E752: 63.16 | F752: 9.13M | G752: -0.0113 | H752: =LN(B752/B753) -> -0.011324437
A753: 45061 | B753: 63.94 | C753: 64.22 | D753: 64.25 | E753: 63.71 | F753: 8.15M | G753: -0.0027

Sheet EXxon mobile
A1: Date | B1: Price | C1: Open | D1: High | E1: Low | F1: Vol. | G1: Change % | H1: Ln return
A2: 46155 | B2: 151.57 | C2: 150.06 | D2: 151.79 | E2: 149.68 | F2: 15.77M | G2: 0.0062 | H2: =LN(B2/B3) -> 0.0062210657 | J2: Daily return | K2: =AVERAGE(H2:H752) -> 0.00048791048
A3: 46154 | B3: 150.63 | C3: 151.25 | D3: 151.81 | E3: 149.77 | F3: 16.44M | G3: 0.0063 | H3: =LN(B3/B4) -> 0.0063268167 | J3: Annual return | K3: =K2*252 -> 0.12295344
A4: 46153 | B4: 149.68 | C4: 146.02 | D4: 149.72 | E4: 146 | F4: 14.85M | G4: 0.0353 | H4: =LN(B4/B5) -> 0.034735863 | J4: Daily volatility | K4: =STDEV(H2:H752) -> 0.014474511
A5: 46150 | B5: 144.57 | C5: 145.85 | D5: 146.5 | E5: 143.92 | F5: 19.55M | G5: -0.0137 | H5: =LN(B5/B6) -> -0.013807535 | J5: annual volatility | K5: =K4*SQRT(252) -> 0.22977574
A6: 46149 | B6: 146.58 | C6: 146.8 | D6: 147.08 | E6: 144.19 | F6: 22.51M | G6: -0.0142 | H6: =LN(B6/B7) -> -0.014292247
A7: 46148 | B7: 148.69 | C7: 149.07 | D7: 150.33 | E7: 147.09 | F7: 20.53M | G7: -0.04 | H7: =LN(B7/B8) -> -0.040787022
A8: 46147 | B8: 154.88 | C8: 153.1 | D8: 155.29 | E8: 152.41 | F8: 12.49M | G8: 0.0077 | H8: =LN(B8/B9) -> 0.0077130369
A9: 46146 | B9: 153.69 | C9: 152.67 | D9: 154.47 | E9: 149.51 | F9: 14.24M | G9: 0.0062 | H9: =LN(B9/B10) -> 0.0061349886
A10: 46143 | B10: 152.75 | C10: 152.61 | D10: 155.01 | E10: 151.13 | F10: 15.46M | G10: -0.0102 | H10: =LN(B10/B11) -> -0.010290569
A11: 46142 | B11: 154.33 | C11: 152.43 | D11: 155.69 | E11: 151.34 | F11: 22.89M | G11: -0.0022 | H11: =LN(B11/B12) -> -0.0022006481
A12: 46141 | B12: 154.67 | C12: 152.01 | D12: 154.95 | E12: 151.01 | F12: 14.67M | G12: 0.0273 | H12: =LN(B12/B13) -> 0.026932139
A13: 46140 | B13: 150.56 | C13: 151.53 | D13: 152.31 | E13: 149.83 | F13: 15.17M | G13: 0.016 | H13: =LN(B13/B14) -> 0.015866442
A14: 46139 | B14: 148.19 | C14: 149.15 | D14: 151.18 | E14: 147.97 | F14: 13.94M | G14: -0.0048 | H14: =LN(B14/B15) -> -0.0048468624
A15: 46136 | B15: 148.91 | C15: 149.64 | D15: 150.3 | E15: 146.95 | F15: 13.74M | G15: -0.0108 | H15: =LN(B15/B16) -> -0.010820303
A16: 46135 | B16: 150.53 | C16: 149.85 | D16: 151.23 | E16: 148.49 | F16: 12.97M | G16: 0.0069 | H16: =LN(B16/B17) -> 0.006866007
A17: 46134 | B17: 149.5 | C17: 149.37 | D17: 150.68 | E17: 148.18 | F17: 13.74M | G17: 0.0077 | H17: =LN(B17/B18) -> 0.0076546402
... A752: 45062 | B752: 102.52 | C752: 104.63 | D752: 104.81 | E752: 102.02 | F752: 14.80M | G752: -0.0243 | H752: =LN(B752/B753) -> -0.024568893
A753: 45061 | B753: 105.07 | C753: 105.51 | D753: 105.93 | E753: 104.58 | F753: 13.72M | G753: -0.0067

Sheet P&G
A1: Date | B1: Price | C1: Open | D1: High | E1: Low | F1: Vol. | G1: Change % | H1: Ln Return
A2: 46155 | B2: 142.24 | C2: 143.15 | D2: 144.67 | E2: 141.66 | F2: 6.69M | G2: -0.0116 | H2: =LN(B2/B3) -> -0.011672332 | J2: Daily return | K2: =AVERAGE(H2:H752) -> -0.00012304173
A3: 46154 | B3: 143.91 | C3: 144.35 | D3: 145.85 | E3: 142.86 | F3: 9.05M | G3: 0.0038 | H3: =LN(B3/B4) -> 0.003829155 | J3: Annual return | K3: =K2*252 -> -0.031006515
A4: 46153 | B4: 143.36 | C4: 145.79 | D4: 145.95 | E4: 141.97 | F4: 7.49M | G4: -0.0209 | H4: =LN(B4/B5) -> -0.021120255 | J4: Daily volatility | K4: =STDEV(H2:H752) -> 0.010848334
A5: 46150 | B5: 146.42 | C5: 146.55 | D5: 147.51 | E5: 146.21 | F5: 5.74M | G5: 0.0025 | H5: =LN(B5/B6) -> 0.002461708 | J5: annual volatility | K5: =K4*SQRT(252) -> 0.17221197
A6: 46149 | B6: 146.06 | C6: 147.99 | D6: 147.99 | E6: 146.01 | F6: 9.55M | G6: -0.0124 | H6: =LN(B6/B7) -> -0.012518874
A7: 46148 | B7: 147.9 | C7: 146.4 | D7: 148.95 | E7: 145.94 | F7: 9.40M | G7: 0.0207 | H7: =LN(B7/B8) -> 0.02049252
A8: 46147 | B8: 144.9 | C8: 143.38 | D8: 145.9 | E8: 142.18 | F8: 7.66M | G8: 0.0103 | H8: =LN(B8/B9) -> 0.010266461
A9: 46146 | B9: 143.42 | C9: 146.06 | D9: 146.06 | E9: 143.27 | F9: 9.64M | G9: -0.0261 | H9: =LN(B9/B10) -> -0.026422343
A10: 46143 | B10: 147.26 | C10: 147.87 | D10: 149.28 | E10: 146.46 | F10: 6.81M | G10: 0.0012 | H10: =LN(B10/B11) -> 0.0011550876
A11: 46142 | B11: 147.09 | C11: 147.09 | D11: 147.72 | E11: 145.95 | F11: 9.49M | G11: 0.0043 | H11: =LN(B11/B12) -> 0.0042922907
A12: 46141 | B12: 146.46 | C12: 148.3 | D12: 148.75 | E12: 145.89 | F12: 9.00M | G12: -0.0182 | H12: =LN(B12/B13) -> -0.018334242
A13: 46140 | B13: 149.17 | C13: 150.03 | D13: 151.18 | E13: 148.43 | F13: 7.97M | G13: 0.0052 | H13: =LN(B13/B14) -> 0.0051752644
A14: 46139 | B14: 148.4 | C14: 147.42 | D14: 149.7 | E14: 147.42 | F14: 9.17M | G14: 0.0015 | H14: =LN(B14/B15) -> 0.0014835797
A15: 46136 | B15: 148.18 | C15: 152.01 | D15: 152.42 | E15: 147.62 | F15: 13.79M | G15: 0.017 | H15: =LN(B15/B16) -> 0.016809406
A16: 46135 | B16: 145.71 | C16: 143.4 | D16: 146.23 | E16: 143.4 | F16: 11.29M | G16: 0.02 | H16: =LN(B16/B17) -> 0.019823216
A17: 46134 | B17: 142.85 | C17: 142.49 | D17: 143.3 | E17: 142.22 | F17: 7.24M | G17: 0.0037 | H17: =LN(B17/B18) -> 0.0037170853
... A752: 45062 | B752: 155.74 | C752: 155.87 | D752: 156.92 | E752: 154.93 | F752: 5.59M | G752: -0.0017 | H752: =LN(B752/B753) -> -0.0017321576
A753: 45061 | B753: 156.01 | C753: 156.61 | D753: 156.75 | E753: 154.64 | F753: 5.41M | G753: 0.0003

Sheet daily returns
A1: Ln returns of 10 stocks
A3: Dates | B3: NVIDIA | C3: APPL | D3: Amazone | E3: Alphabet | F3: META | G3: J&J | H3: JPM | I3: Coca-Cola | J3: Exxom mobile | K3: P&G
A4: 46155 | B4: 0.022615773 | C4: 0.013711536 | D4: 0.016083937 | E4: 0.038664512 | F4: 0.022351971 | G4: 0.027097638 | H4: -0.015302796 | I4: 0.0028698005 | J4: 0.0062210657 | K4: -0.011672332
A5: 46154 | B5: 0.006087884 | C5: 0.0072172983 | D5: -0.011854816 | E5: -0.0033247882 | F5: 0.0068893488 | G5: 0.012699581 | H5: 0.016135782 | I5: 0.017266797 | J5: 0.0063268167 | K5: 0.003829155
A6: 46153 | B6: 0.019511018 | C6: -0.0021843012 | D6: -0.013624742 | E6: -0.030809085 | F6: -0.017824368 | G6: 0.00049689442 | H6: -0.0069756137 | I6: 0.0030557701 | J6: 0.034735863 | K6: -0.021120255
A7: 46150 | B7: 0.01734283 | C7: 0.02025002 | D7: 0.005553016 | E7: 0.0070356704 | F7: -0.011708819 | G7: -0.0053624264 | H7: -0.013708977 | I7: -0.00012751036 | J7: -0.013807535 | K7: 0.002461708
A8: 46149 | B8: 0.017504561 | C8: -0.00024349944 | D8: -0.013988803 | E8: -0.00012562341 | F8: 0.0063918766 | G8: -0.0094380411 | H8: -0.027788062 | I8: -0.010148508 | J8: -0.014292247 | K8: -0.012518874
A9: 46148 | B9: 0.056058007 | C9: 0.011649802 | D9: 0.0052503129 | E9: 0.024439529 | F9: 0.013006818 | G9: -0.0041317783 | H9: 0.01762019 | I9: 0.0095111997 | J9: -0.040787022 | K9: 0.02049252
A10: 46147 | B10: -0.010025908 | C10: 0.026204241 | D10: 0.0054985476 | E10: 0.013425456 | F10: -0.0089685224 | G10: 0.0060033532 | H10: 0.005672165 | I10: 0.0037020531 | J10: 0.0077130369 | K10: 0.010266461
A11: 46146 | B11: 0.00015116015 | C11: -0.011885879 | D11: 0.014029213 | E11: -0.0063464202 | F11: 0.0027396154 | G11: -0.013248161 | H11: -0.015545691 | I11: -0.004975452 | J11: 0.0061349886 | K11: -0.026422343
A12: 46143 | B12: -0.0056278728 | C12: 0.031879978 | D12: 0.012000444 | E12: 0.0023102192 | F12: -0.0051939657 | G12: -0.01164025 | H12: -0.0024292804 | I12: -0.0022880396 | J12: -0.010290569 | K12: 0.0011550876
A13: 46142 | B13: -0.047364657 | C13: 0.00435811 | D13: 0.0076501036 | E13: 0.094962008 | F13: -0.089378203 | G13: 0.010936242 | H13: 0.012787734 | I13: -0.0013956736 | J13: -0.0022006481 | K13: 0.0042922907
A14: 46141 | B14: -0.01856026 | C14: -0.0019967467 | D14: 0.012778993 | E14: 0.0004573258 | F14: -0.0033122988 | G14: -0.0019334716 | H14: -0.0070888004 | I14: 0.0066149586 | J14: 0.026932139 | K14: -0.018334242
A15: 46140 | B15: -0.016008532 | C15: 0.01151744 | D15: -0.0054529531 | E15: -0.0015997261 | F15: -0.010785609 | G15: 0.010813779 | H15: -0.00057777494 | I15: 0.03784833 | J15: 0.015866442 | K15: 0.0051752644
... A754: 45062 | B754: 0.0089409124 | C754: 0 | D754: 0.019591009 | E754: 0.025422944 | F754: -0.00016747614 | G754: -0.0013170688 | H754: -0.0067520197 | I754: -0.011324437 | J754: -0.024568893 | K754: -0.0017321576

Sheet Cov matrix
A1: Covariance matrix
B3: NVIDIA | C3: APPL | D3: Amazone | E3: Alphabet | F3: META | G3: J&J | H3: JPM | I3: Coca-Cola | J3: Exxom mobile | K3: P&G
A4: NVIDIA | B4: =VARP('daily returns'!$B$4:$B$754) -> 0.00092729218
A5: APPL | B5: 0.00017100245 | C5: =VARP('daily returns'!$C$4:$C$754) -> 0.0002610575
A6: Amazone | B6: 0.00027212108 | C6: 0.00013707377 | D6: =VARP('daily returns'!$D$4:$D$754) -> 0.0003797736
A7: Alphabet | B7: 0.00022232633 | C7: 0.00012721327 | D7: 0.00019571812 | E7: =VARP('daily returns'!$E$4:$E$754) -> 0.00034610361
A8: META | B8: 0.00032305252 | C8: 0.00013622745 | D8: 0.00026418477 | E8: 0.00017673605 | F8: =VARP('daily returns'!$F$4:$F$754) -> 0.00050333609
A9: J&J | B9: -8.299172e-05 | C9: 7.249162e-06 | D9: -2.9533307e-05 | E9: -9.261427e-06 | F9: -3.4338921e-05 | G9: =VARP('daily returns'!$G$4:$G$754) -> 0.00011780392
A10: JPM | B10: 0.00011284267 | C10: 7.1227395e-05 | D10: 9.4337123e-05 | E10: 6.9378958e-05 | F10: 9.1554663e-05 | G10: 1.7963209e-05 | H10: =VARP('daily returns'!$H$4:$H$754) -> 0.00020556332
A11: Coca-Cola | B11: -5.977905e-05 | C11: 1.8530569e-05 | D11: -1.5823697e-05 | E11: -7.7885853e-06 | F11: -1.458466e-05 | G11: 4.2370686e-05 | H11: 1.0767383e-05 | I11: =VARP('daily returns'!$I$4:$I$754) -> 9.4078039e-05
A12: Exxom mobile | B12: -1.7607511e-05 | C12: 2.9283378e-05 | D12: 4.5727803e-06 | E12: -1.2378339e-05 | F12: -2.5387001e-06 | G12: 2.2255642e-05 | H12: 5.3471212e-05 | I12: 1.8307346e-05 | J12: =VARP('daily returns'!$J$4:$J$754) -> 0.00020923249
A13: P&G | B13: -5.3360702e-05 | C13: 2.4454183e-05 | D13: -4.1320174e-06 | E13: -3.4488409e-06 | F13: -1.4639121e-06 | G13: 4.2323201e-05 | H13: 1.0693766e-05 | I13: 5.95498e-05 | J13: 1.3016095e-05 | K13: =VARP('daily returns'!$K$4:$K$754) -> 0.00011752965

Sheet corr. matrix
A1: Correlation matrix
B3: NVIDIA | C3: APPL | D3: Amazone | E3: Alphabet | F3: META | G3: J&J | H3: JPM | I3: Coca-Cola | J3: Exxom mobile | K3: P&G
A4: NVIDIA | B4: 1
A5: APPL | B5: 0.34755692 | C5: 1
A6: Amazone | B6: 0.45855508 | C6: 0.4353353 | D6: 1
A7: Alphabet | B7: 0.39244567 | C7: 0.4232152 | D7: 0.53984066 | E7: 1
A8: META | B8: 0.47286351 | C8: 0.37580927 | D8: 0.60424957 | E8: 0.42344113 | F8: 1
A9: J&J | B9: -0.25109994 | C9: 0.041337086 | D9: -0.13962714 | E9: -0.045866434 | F9: -0.14101904 | G9: 1
A10: JPM | B10: 0.25845935 | C10: 0.30747241 | D10: 0.33763498 | E10: 0.26010691 | F10: 0.28462865 | G10: 0.11543334 | H10: 1
A11: Coca-Cola | B11: -0.20239351 | C11: 0.1182433 | D11: -0.083714645 | E11: -0.043162976 | F11: -0.067022889 | G11: 0.40247741 | H11: 0.077427143 | I11: 1
A12: Exxom mobile | B12: -0.039973769 | C12: 0.12529638 | D12: 0.016221963 | E12: -0.045998615 | F12: -0.0078229006 | G12: 0.14175739 | H12: 0.25782953 | I12: 0.13048683 | J12: 1
A13: P&G | B13: -0.16163653 | C13: 0.13960833 | D13: -0.019558072 | E13: -0.01710001 | F13: -0.006018832 | G13: 0.35968715 | H13: 0.068799316 | I13: 0.56632072 | J13: 0.083002741 | K13: 1

Sheet Sheet2
A1: 0.73898832 | B1: =RAND() -> 0.85369642 | C1: =RANDBETWEEN(1,2000) -> 858 | D1: =NORMSINV(B1) -> 1.0524194
A2: -0.39435463 | B2: =RAND() -> 0.15536427 | C2: =RANDBETWEEN(1,2000) -> 107 | D2: =NORMSINV(B2) -> -1.0136945
A3: 0.008835741 | B3: =RAND() -> 0.78782707 | C3: =RANDBETWEEN(1,2000) -> 1766 | D3: =NORMSINV(B3) -> 0.79890436
A4: 0.30087222 | B4: =RAND() -> 0.16186479 | C4: =RANDBETWEEN(1,2000) -> 1923 | D4: =NORMSINV(B4) -> -0.98682268
A5: -0.57919692 | B5: =RAND() -> 0.29459668 | C5: =RANDBETWEEN(1,2000) -> 954 | D5: =NORMSINV(B5) -> -0.54000534
A6: -0.047025424 | B6: =RAND() -> 0.82450554 | C6: =RANDBETWEEN(1,2000) -> 1239 | D6: =NORMSINV(B6) -> 0.93267281
A7: -0.9047244 | B7: =RAND() -> 0.44312773 | C7: =RANDBETWEEN(1,2000) -> 976 | D7: =NORMSINV(B7) -> -0.14304397
A8: -1.4950865 | B8: =RAND() -> 0.17061804 | C8: =RANDBETWEEN(1,2000) -> 85 | D8: =NORMSINV(B8) -> -0.95172575
A9: -0.6330697 | B9: =RAND() -> 0.82016698 | C9: =RANDBETWEEN(1,2000) -> 1077 | D9: =NORMSINV(B9) -> 0.91600161
A10: -0.94448751 | B10: =RAND() -> 0.60953898 | C10: =RANDBETWEEN(1,2000) -> 1000 | D10: =NORMSINV(B10) -> 0.27811765
A11: -0.47989033 | B11: =RAND() -> 0.56315729 | C11: =RANDBETWEEN(1,2000) -> 1225 | D11: =NORMSINV(B11) -> 0.15897901
A12: 0.50137487 | B12: =RAND() -> 0.70688763 | C12: =RANDBETWEEN(1,2000) -> 167 | D12: =NORMSINV(B12) -> 0.54431498
... A2000: 0.58535989 | B2000: =RAND() -> 0.83914627 | C2000: =RANDBETWEEN(1,2000) -> 1709 | D2000: =NORMSINV(B2000) -> 0.99095519

Sheet Final
A1: Stock | B1: daily returs | C1: annual returns | D1: daily volatility | E1: annual volatility
A2: NVIDIA | B2: 0.0027353027 | C2: 0.68929627 | D2: 0.030471767 | E2: 0.4837243
A3: APPL | B3: 0.00073516288 | C3: 0.18526105 | D3: 0.016168042 | E3: 0.25665971
A4: Amazone | B4: 0.0011818548 | C4: 0.29782741 | D4: 0.019500768 | E4: 0.3095651
A5: Alphabet | B5: 0.0016511532 | C5: 0.41609062 | D5: 0.018616259 | E5: 0.29552394
A6: META | B6: 0.0012628383 | C6: 0.31823525 | D6: 0.022450105 | E6: 0.35638437
A7: J&J | B7: 0.00048940929 | C7: 0.12333114 | D7: 0.010860985 | E7: 0.17241279
A8: JPM | B8: 0.0010621018 | C8: 0.26764965 | D8: 0.014347035 | E8: 0.22775212
A9: Coca-Cola | B9: 0.00030269803 | C9: 0.076279904 | D9: 0.0097058476 | E9: 0.15407555
A10: Exxom mobile | B10: 0.00048791048 | C10: 0.12295344 | D10: 0.014474511 | E10: 0.22977574
A11: P&G | B11: -0.00012304173 | C11: -0.031006515 | D11: 0.010848334 | E11: 0.17221197
A13: Covariance matrix
B14: NVIDIA | C14: APPL | D14: Amazone | E14: Alphabet | F14: META | G14: J&J | H14: JPM | I14: Coca-Cola | J14: Exxom mobile | K14: P&G
A15: NVIDIA | B15: 0.00092729218 | C15: 0.00017100245 | D15: 0.00027212108 | E15: 0.00022232633 | F15: 0.00032305252 | G15: -8.299172e-05 | H15: 0.00011284267 | I15: -5.977905e-05 | J15: -1.7607511e-05 | K15: -5.3360702e-05
A16: APPL | B16: 0.00017100245 | C16: 0.0002610575 | D16: 0.00013707377 | E16: 0.00012721327 | F16: 0.00013622745 | G16: 7.249162e-06 | H16: 7.1227395e-05 | I16: 1.8530569e-05 | J16: 2.9283378e-05 | K16: 2.4454183e-05
A17: Amazone | B17: 0.00027212108 | C17: 0.00013707377 | D17: 0.0003797736 | E17: 0.00019571812 | F17: 0.00026418477 | G17: -2.9533307e-05 | H17: 9.4337123e-05 | I17: -1.5823697e-05 | J17: 4.5727803e-06 | K17: -4.1320174e-06
A18: Alphabet | B18: 0.00022232633 | C18: 0.00012721327 | D18: 0.00019571812 | E18: 0.00034610361 | F18: 0.00017673605 | G18: -9.261427e-06 | H18: 6.9378958e-05 | I18: -7.7885853e-06 | J18: -1.2378339e-05 | K18: -3.4488409e-06
A19: META | B19: 0.00032305252 | C19: 0.00013622745 | D19: 0.00026418477 | E19: 0.00017673605 | F19: 0.00050333609 | G19: -3.4338921e-05 | H19: 9.1554663e-05 | I19: -1.458466e-05 | J19: -2.5387001e-06 | K19: -1.4639121e-06
A20: J&J | B20: -8.299172e-05 | C20: 7.249162e-06 | D20: -2.9533307e-05 | E20: -9.261427e-06 | F20: -3.4338921e-05 | G20: 0.00011780392 | H20: 1.7963209e-05 | I20: 4.2370686e-05 | J20: 2.2255642e-05 | K20: 4.2323201e-05
A21: JPM | B21: 0.00011284267 | C21: 7.1227395e-05 | D21: 9.4337123e-05 | E21: 6.9378958e-05 | F21: 9.1554663e-05 | G21: 1.7963209e-05 | H21: 0.00020556332 | I21: 1.0767383e-05 | J21: 5.3471212e-05 | K21: 1.0693766e-05
A22: Coca-Cola | B22: -5.977905e-05 | C22: 1.8530569e-05 | D22: -1.5823697e-05 | E22: -7.7885853e-06 | F22: -1.458466e-05 | G22: 4.2370686e-05 | H22: 1.0767383e-05 | I22: 9.4078039e-05 | J22: 1.8307346e-05 | K22: 5.95498e-05
A23: Exxom mobile | B23: -1.7607511e-05 | C23: 2.9283378e-05 | D23: 4.5727803e-06 | E23: -1.2378339e-05 | F23: -2.5387001e-06 | G23: 2.2255642e-05 | H23: 5.3471212e-05 | I23: 1.8307346e-05 | J23: 0.00020923249 | K23: 1.3016095e-05
A24: P&G | B24: -5.3360702e-05 | C24: 2.4454183e-05 | D24: -4.1320174e-06 | E24: -3.4488409e-06 | F24: -1.4639121e-06 | G24: 4.2323201e-05 | H24: 1.0693766e-05 | I24: 5.95498e-05 | J24: 1.3016095e-05 | K24: 0.00011752965 | M24: annual covariance matrix is positive definite.
A26: Annual cov matrix | M26: Matrix size | N26: Determinant
B27: NVIDIA | C27: APPL | D27: Amazone | E27: Alphabet | F27: META | G27: J&J | H27: JPM | I27: Coca-Cola | J27: Exxom mobile | K27: P&G | M27: 1*1 | N27: =MDETERM(B28) -> 0.23367763
A28: NVIDIA | B28: =B15*252 -> 0.23367763 | C28: 0.043092617 | D28: 0.068574513 | E28: 0.056026236 | F28: 0.081409235 | G28: -0.020913913 | H28: 0.028436354 | I28: -0.015064321 | J28: -0.0044370927 | K28: -0.013446897 | M28: 2*2 | N28: =MDETERM(B28:C29) -> 0.013515858
A29: APPL | B29: =B16*252 -> 0.043092617 | C29: =C16*252 -> 0.065786491 | D29: 0.065786491 | E29: 0.032057744 | F29: 0.034329316 | G29: 0.0018267888 | H29: 0.017949304 | I29: 0.0046697033 | J29: 0.0073794111 | K29: 0.006162454 | M29: 3*3 | N29: =MDETERM(B28:D30) -> 0.00074960938
A30: Amazone | B30: =B17*252 -> 0.068574513 | C30: =C17*252 -> 0.03454259 | D30: =D17*252 -> 0.095702947 | E30: 0.049320967 | F30: 0.066574562 | G30: -0.0074423934 | H30: 0.023772955 | I30: -0.0039875716 | J30: 0.0011523406 | K30: -0.0010412684 | M30: 4*4 | N30: =MDETERM(B28:E31) -> 4.4887874e-05
A31: Alphabet | B31: =B18*252 -> 0.056026236 | C31: =C18*252 -> 0.032057744 | D31: =D18*252 -> 0.049320967 | E31: =E18*252 -> 0.08721811 | F31: 0.044537485 | G31: -0.0023338796 | H31: 0.017483497 | I31: -0.0019627235 | J31: -0.0031193415 | K31: -0.00086910789 | M31: 5*5 | N31: =MDETERM(B28:F32) -> 3.3693657e-06
A32: META | B32: =B19*252 -> 0.081409235 | C32: =C19*252 -> 0.034329316 | D32: =D19*252 -> 0.066574562 | E32: =E19*252 -> 0.044537485 | F32: =F19*252 -> 0.1268407 | G32: -0.0086534081 | H32: 0.023071775 | I32: -0.0036753344 | J32: -0.00063975243 | K32: -0.00036890584 | M32: 6*6 | N32: =MDETERM(B28:G33) -> 9.0233096e-08
A33: J&J | B33: =B20*252 -> -0.020913913 | C33: =C20*252 -> 0.0018267888 | D33: =D20*252 -> -0.0074423934 | E33: =E20*252 -> -0.0023338796 | F33: =F20*252 -> -0.0086534081 | G33: =G20*252 -> 0.029686587 | H33: 0.0045267287 | I33: 0.010677413 | J33: 0.0056084218 | K33: 0.010665447 | M33: 7*7 | N33: =MDETERM(B28:H34) -> 3.855896e-09
A34: JPM | B34: =B21*252 -> 0.028436354 | C34: =C21*252 -> 0.017949304 | D34: =D21*252 -> 0.023772955 | E34: =E21*252 -> 0.017483497 | F34: =F21*252 -> 0.023071775 | G34: =G21*252 -> 0.0045267287 | H34: =H21*252 -> 0.051801957 | I34: 0.0027133806 | J34: 0.013474745 | K34: 0.0026948289 | M34: 8*8 | N34: =MDETERM(B28:I35) -> 7.2851866e-11
A35: Coca-Cola | B35: =B22*252 -> -0.015064321 | C35: =C22*252 -> 0.0046697033 | D35: =D22*252 -> -0.0039875716 | E35: =E22*252 -> -0.0019627235 | F35: =F22*252 -> -0.0036753344 | G35: =G22*252 -> 0.010677413 | H35: =H22*252 -> 0.0027133806 | I35: =I22*252 -> 0.023707666 | J35: 0.0046134511 | K35: 0.015006549 | M35: 9*9 | N35: =MDETERM(B28:J36) -> 3.4283225e-12
A36: Exxom mobile | B36: =B23*252 -> -0.0044370927 | C36: =C23*252 -> 0.0073794111 | D36: =D23*252 -> 0.0011523406 | E36: =E23*252 -> -0.0031193415 | F36: =F23*252 -> -0.00063975243 | G36: =G23*252 -> 0.0056084218 | H36: =H23*252 -> 0.013474745 | I36: =I23*252 -> 0.0046134511 | J36: =J23*252 -> 0.052726587 | K36: 0.003280056 | M36: 10*10 | N36: =MDETERM(B28:K37) -> 6.5807293e-14
A37: P&G | B37: =B24*252 -> -0.013446897 | C37: =C24*252 -> 0.006162454 | D37: =D24*252 -> -0.0010412684 | E37: =E24*252 -> -0.00086910789 | F37: =F24*252 -> -0.00036890584 | G37: =G24*252 -> 0.010665447 | H37: =H24*252 -> 0.0026948289 | I37: =I24*252 -> 0.015006549 | ... K37: =K24*252 -> 0.029617473
A40: Correlation matrix
B41: NVIDIA | C41: APPL | D41: Amazone | E41: Alphabet | F41: META | G41: J&J | H41: JPM | I41: Coca-Cola | J41: Exxom mobile | K41: P&G
A42: NVIDIA | B42: 1 | C42: 0.34755692 | D42: 0.45855508 | E42: 0.39244567 | F42: 0.47286351 | G42: -0.25109994 | H42: 0.25845935 | I42: -0.20239351 | J42: -0.039973769 | K42: -0.16163653
A43: APPL | B43: 0.34755692 | C43: 1 | D43: 0.4353353 | E43: 0.4232152 | F43: 0.37580927 | G43: 0.041337086 | H43: 0.30747241 | I43: 0.1182433 | J43: 0.12529638 | K43: 0.13960833
A44: Amazone | B44: 0.45855508 | C44: 0.4353353 | D44: 1 | E44: 0.53984066 | F44: 0.60424957 | G44: -0.13962714 | H44: 0.33763498 | I44: -0.083714645 | J44: 0.016221963 | K44: -0.019558072
...

Sheet Sheet1
A1: 225.83 | B1: 298.87 | C1: 270.13 | D1: 402.62 | E1: 616.63 | F1: 230.42 | G1: 300.25 | H1: 80.26 | I1: 151.57 | J1: 142.24
A2: 220.78 | B2: 294.8 | C2: 265.82 | D2: 387.35 | E2: 603 | F2: 224.26 | G2: 304.88 | H2: 80.03 | I2: 150.63 | J2: 143.91
A3: 219.44 | B3: 292.68 | C3: 268.99 | D3: 388.64 | E3: 598.86 | F3: 221.43 | G3: 300 | H3: 78.66 | I3: 149.68 | J3: 143.36
A4: 215.2 | B4: 293.32 | C4: 272.68 | D4: 400.8 | E4: 609.63 | F4: 221.32 | G4: 302.1 | H4: 78.42 | I4: 144.57 | J4: 146.42
A5: 211.5 | B5: 287.44 | C5: 271.17 | D5: 397.99 | E5: 616.81 | F5: 222.51 | G5: 306.27 | H5: 78.43 | I5: 146.58 | J5: 146.06
A6: 207.83 | B6: 287.51 | C6: 274.99 | D6: 398.04 | E6: 612.88 | F6: 224.62 | G6: 314.9 | H6: 79.23 | I6: 148.69 | J6: 147.9
A7: 196.5 | B7: 284.18 | C7: 273.55 | D7: 388.43 | E7: 604.96 | F7: 225.55 | G7: 309.4 | H7: 78.48 | I7: 154.88 | J7: 144.9
A8: 198.48 | B8: 276.83 | C8: 272.05 | D8: 383.25 | E8: 610.41 | F8: 224.2 | G8: 307.65 | H8: 78.19 | I8: 153.69 | J8: 143.42
A9: 198.45 | B9: 280.14 | C9: 268.26 | D9: 385.69 | E9: 608.74 | F9: 227.19 | G9: 312.47 | H9: 78.58 | I9: 152.75 | J9: 147.26
A10: 199.57 | B10: 271.35 | C10: 265.06 | D10: 384.8 | E10: 611.91 | F10: 229.85 | G10: 313.23 | H10: 78.76 | I10: 154.33 | J10: 147.09
A11: 209.25 | B11: 270.17 | C11: 263.04 | D11: 349.94 | E11: 669.12 | F11: 227.35 | G11: 309.25 | H11: 78.87 | I11: 154.67 | J11: 146.46
A12: 213.17 | B12: 270.71 | C12: 259.7 | D12: 349.78 | E12: 671.34 | F12: 227.79 | G12: 311.45 | H12: 78.35 | I12: 150.56 | J12: 149.17
... A752: 28.95 | B752: 172.07 | C752: 111.2 | D752: 116.51 | E752: 238.86 | F752: 159.55 | G752: 135.23 | H752: 63.94 | I752: 105.07 | J752: 156.01
